INFO:app.main:获取对话37edb7a3-bda4-441f-8bed-d09f8b23cb9c的历史消息
INFO:httpx:HTTP Request: GET https://fmqreoeqzqdaqdtgqzkc.supabase.co/rest/v1/conversations?select=user_id&id=eq.37edb7a3-bda4-441f-8bed-d09f8b23cb9c "HTTP/2 200 OK"
INFO:httpx:HTTP Request: GET https://fmqreoeqzqdaqdtgqzkc.supabase.co/rest/v1/messages?select=content%2Cis_user%2Ccreated_at&conversation_id=eq.37edb7a3-bda4-441f-8bed-d09f8b23cb9c&order=created_at "HTTP/2 200 OK"
INFO:app.main:正在为用户e3ca61ba-bca0-44f9-9f52-48219ed3ed9e生成回复
INFO:httpx:HTTP Request: POST https://api.openai.com/v1/chat/completions "HTTP/1.1 200 OK"
INFO:app.main:异步保存消息
INFO:     172.31.128.64:54028 - "POST /api/chat/37edb7a3-bda4-441f-8bed-d09f8b23cb9c HTTP/1.1" 200 OK
INFO:httpx:HTTP Request: POST https://fmqreoeqzqdaqdtgqzkc.supabase.co/rest/v1/messages "HTTP/2 401 Unauthorized"
ERROR:app.services.supabase:保存消息失败:
错误码: unknown
错误信息: {'code': '42501', 'details': None, 'hint': None, 'message': 'new row violates row-level security policy for table "messages"'}
详细信息: None
表: messages
操作: insert
ERROR:    Exception in ASGI application
Traceback (most recent call last):
  File "/home/runner/workspace/app/services/supabase.py", line 99, in save_message
    .execute() \
  File "/home/runner/workspace/.pythonlibs/lib/python3.10/site-packages/postgrest/_sync/request_builder.py", line 78, in execute
    raise APIError(r.json())
postgrest.exceptions.APIError: {'code': '42501', 'details': None, 'hint': None, 'message': 'new row violates row-level security policy for table "messages"'}

During handling of the above exception, another exception occurred:

Traceback (most recent call last):
  File "/home/runner/workspace/.pythonlibs/lib/python3.10/site-packages/uvicorn/protocols/http/h11_impl.py", line 403, in run_asgi
    result = await app(  # type: ignore[func-returns-value]
  File "/home/runner/workspace/.pythonlibs/lib/python3.10/site-packages/uvicorn/middleware/proxy_headers.py", line 60, in __call__
    return await self.app(scope, receive, send)
  File "/home/runner/workspace/.pythonlibs/lib/python3.10/site-packages/fastapi/applications.py", line 1054, in __call__
    await super().__call__(scope, receive, send)
  File "/home/runner/workspace/.pythonlibs/lib/python3.10/site-packages/starlette/applications.py", line 112, in __call__
    await self.middleware_stack(scope, receive, send)
  File "/home/runner/workspace/.pythonlibs/lib/python3.10/site-packages/starlette/middleware/errors.py", line 187, in __call__
    raise exc
  File "/home/runner/workspace/.pythonlibs/lib/python3.10/site-packages/starlette/middleware/errors.py", line 165, in __call__
    await self.app(scope, receive, _send)
  File "/home/runner/workspace/.pythonlibs/lib/python3.10/site-packages/starlette/middleware/cors.py", line 93, in __call__
    await self.simple_response(scope, receive, send, request_headers=headers)
  File "/home/runner/workspace/.pythonlibs/lib/python3.10/site-packages/starlette/middleware/cors.py", line 144, in simple_response
    await self.app(scope, receive, send)
  File "/home/runner/workspace/.pythonlibs/lib/python3.10/site-packages/starlette/middleware/exceptions.py", line 62, in __call__
    await wrap_app_handling_exceptions(self.app, conn)(scope, receive, send)
  File "/home/runner/workspace/.pythonlibs/lib/python3.10/site-packages/starlette/_exception_handler.py", line 53, in wrapped_app
    raise exc
  File "/home/runner/workspace/.pythonlibs/lib/python3.10/site-packages/starlette/_exception_handler.py", line 42, in wrapped_app
    await app(scope, receive, sender)
  File "/home/runner/workspace/.pythonlibs/lib/python3.10/site-packages/starlette/routing.py", line 715, in __call__
    await self.middleware_stack(scope, receive, send)
  File "/home/runner/workspace/.pythonlibs/lib/python3.10/site-packages/starlette/routing.py", line 735, in app
    await route.handle(scope, receive, send)
  File "/home/runner/workspace/.pythonlibs/lib/python3.10/site-packages/starlette/routing.py", line 288, in handle
    await self.app(scope, receive, send)
  File "/home/runner/workspace/.pythonlibs/lib/python3.10/site-packages/starlette/routing.py", line 76, in app
    await wrap_app_handling_exceptions(app, request)(scope, receive, send)
  File "/home/runner/workspace/.pythonlibs/lib/python3.10/site-packages/starlette/_exception_handler.py", line 53, in wrapped_app
    raise exc
  File "/home/runner/workspace/.pythonlibs/lib/python3.10/site-packages/starlette/_exception_handler.py", line 42, in wrapped_app
    await app(scope, receive, sender)
  File "/home/runner/workspace/.pythonlibs/lib/python3.10/site-packages/starlette/routing.py", line 74, in app
    await response(scope, receive, send)
  File "/home/runner/workspace/.pythonlibs/lib/python3.10/site-packages/starlette/responses.py", line 159, in __call__
    await self.background()
  File "/home/runner/workspace/.pythonlibs/lib/python3.10/site-packages/starlette/background.py", line 41, in __call__
    await task()
  File "/home/runner/workspace/.pythonlibs/lib/python3.10/site-packages/starlette/background.py", line 28, in __call__
    await run_in_threadpool(self.func, *self.args, **self.kwargs)
  File "/home/runner/workspace/.pythonlibs/lib/python3.10/site-packages/starlette/concurrency.py", line 37, in run_in_threadpool
    return await anyio.to_thread.run_sync(func)
  File "/home/runner/workspace/.pythonlibs/lib/python3.10/site-packages/anyio/to_thread.py", line 56, in run_sync
    return await get_async_backend().run_sync_in_worker_thread(
  File "/home/runner/workspace/.pythonlibs/lib/python3.10/site-packages/anyio/_backends/_asyncio.py", line 2461, in run_sync_in_worker_thread
    return await future
  File "/home/runner/workspace/.pythonlibs/lib/python3.10/site-packages/anyio/_backends/_asyncio.py", line 962, in run
    result = context.run(func, *args)
  File "/home/runner/workspace/app/services/supabase.py", line 118, in save_message
    raise Exception(f"保存消息失败: 错误码={error_code}, 信息={error_message}")
Exception: 保存消息失败: 错误码=unknown, 信息={'code': '42501', 'details': None, 'hint': None, 'message': 'new row violates row-level security policy for table "messages"'}