INFO:app.main:收到文档处理请求: {'file_id': '71b01771-454e-42b9-a2e4-d1b2e692667b', 'url': 'https://fmqreoeqzqdaqdtgqzkc.supabase.co/storage/v1/object/public/files/8447d0a2-d505-47b6-bd50-51a5c97616e2/x1qkzhalec.pdf'}
INFO:app.main:开始处理文档: file_id=71b01771-454e-42b9-a2e4-d1b2e692667b, url=https://fmqreoeqzqdaqdtgqzkc.supabase.co/storage/v1/object/public/files/8447d0a2-d505-47b6-bd50-51a5c97616e2/x1qkzhalec.pdf
INFO:app.main:文档处理任务已添加到后台: file_id=71b01771-454e-42b9-a2e4-d1b2e692667b
INFO:     172.31.128.83:47868 - "POST /api/documents/process HTTP/1.1" 200 OK
INFO:app.services.document_service:开始处理文件: file_id=71b01771-454e-42b9-a2e4-d1b2e692667b, url=https://fmqreoeqzqdaqdtgqzkc.supabase.co/storage/v1/object/public/files/8447d0a2-d505-47b6-bd50-51a5c97616e2/x1qkzhalec.pdf
INFO:app.services.document_service:更新文件状态为处理中: file_id=71b01771-454e-42b9-a2e4-d1b2e692667b
ERROR:app.services.document_service:处理文件失败: name 'datetime' is not defined
ERROR:    Exception in ASGI application
Traceback (most recent call last):
  File "/home/runner/workspace/app/services/document_service.py", line 35, in process_file
    await supabase_service.update_file_status(file_id, "processing")
  File "/home/runner/workspace/app/services/supabase.py", line 79, in update_file_status
    "updated_at": datetime.now().isoformat(),
NameError: name 'datetime' is not defined

During handling of the above exception, another exception occurred:

Traceback (most recent call last):
  File "/home/runner/workspace/.pythonlibs/lib/python3.10/site-packages/uvicorn/protocols/http/h11_impl.py", line 403, in run_asgi
    result = await app(  # type: ignore[func-returns-value]
  File "/home/runner/workspace/.pythonlibs/lib/python3.10/site-packages/uvicorn/middleware/proxy_headers.py", line 60, in __call__
    return await self.app(scope, receive, send)
  File "/home/runner/workspace/.pythonlibs/lib/python3.10/site-packages/fastapi/applications.py", line 1054, in __call__
    await super().__call__(scope, receive, send)
  File "/home/runner/workspace/.pythonlibs/lib/python3.10/site-packages/starlette/applications.py", line 112, in __call__
    await self.middleware_stack(scope, receive, send)
  File "/home/runner/workspace/.pythonlibs/lib/python3.10/site-packages/starlette/middleware/errors.py", line 187, in __call__
    raise exc
  File "/home/runner/workspace/.pythonlibs/lib/python3.10/site-packages/starlette/middleware/errors.py", line 165, in __call__
    await self.app(scope, receive, _send)
  File "/home/runner/workspace/.pythonlibs/lib/python3.10/site-packages/starlette/middleware/cors.py", line 93, in __call__
    await self.simple_response(scope, receive, send, request_headers=headers)
  File "/home/runner/workspace/.pythonlibs/lib/python3.10/site-packages/starlette/middleware/cors.py", line 144, in simple_response
    await self.app(scope, receive, send)
  File "/home/runner/workspace/.pythonlibs/lib/python3.10/site-packages/starlette/middleware/exceptions.py", line 62, in __call__
    await wrap_app_handling_exceptions(self.app, conn)(scope, receive, send)
  File "/home/runner/workspace/.pythonlibs/lib/python3.10/site-packages/starlette/_exception_handler.py", line 53, in wrapped_app
    raise exc
  File "/home/runner/workspace/.pythonlibs/lib/python3.10/site-packages/starlette/_exception_handler.py", line 42, in wrapped_app
    await app(scope, receive, sender)
  File "/home/runner/workspace/.pythonlibs/lib/python3.10/site-packages/starlette/routing.py", line 715, in __call__
    await self.middleware_stack(scope, receive, send)
  File "/home/runner/workspace/.pythonlibs/lib/python3.10/site-packages/starlette/routing.py", line 735, in app
    await route.handle(scope, receive, send)
  File "/home/runner/workspace/.pythonlibs/lib/python3.10/site-packages/starlette/routing.py", line 288, in handle
    await self.app(scope, receive, send)
  File "/home/runner/workspace/.pythonlibs/lib/python3.10/site-packages/starlette/routing.py", line 76, in app
    await wrap_app_handling_exceptions(app, request)(scope, receive, send)
  File "/home/runner/workspace/.pythonlibs/lib/python3.10/site-packages/starlette/_exception_handler.py", line 53, in wrapped_app
    raise exc
  File "/home/runner/workspace/.pythonlibs/lib/python3.10/site-packages/starlette/_exception_handler.py", line 42, in wrapped_app
    await app(scope, receive, sender)
  File "/home/runner/workspace/.pythonlibs/lib/python3.10/site-packages/starlette/routing.py", line 74, in app
    await response(scope, receive, send)
  File "/home/runner/workspace/.pythonlibs/lib/python3.10/site-packages/starlette/responses.py", line 159, in __call__
    await self.background()
  File "/home/runner/workspace/.pythonlibs/lib/python3.10/site-packages/starlette/background.py", line 41, in __call__
    await task()
  File "/home/runner/workspace/.pythonlibs/lib/python3.10/site-packages/starlette/background.py", line 26, in __call__
    await self.func(*self.args, **self.kwargs)
  File "/home/runner/workspace/app/services/document_service.py", line 76, in process_file
    await supabase_service.update_file_status(file_id, "failed")
  File "/home/runner/workspace/app/services/supabase.py", line 79, in update_file_status
    "updated_at": datetime.now().isoformat(),
NameError: name 'datetime' is not defined