INFO:app.main:收到文档处理请求: {'file_id': 'f09e21b7-78d5-441e-bc47-1e17ec9af8bb', 'url': 'https://fmqreoeqzqdaqdtgqzkc.supabase.co/storage/v1/object/public/files/8447d0a2-d505-47b6-bd50-51a5c97616e2/1fyn5hnrpid.pdf'}
INFO:app.main:开始处理文档: file_id=f09e21b7-78d5-441e-bc47-1e17ec9af8bb, url=https://fmqreoeqzqdaqdtgqzkc.supabase.co/storage/v1/object/public/files/8447d0a2-d505-47b6-bd50-51a5c97616e2/1fyn5hnrpid.pdf
INFO:app.main:文档处理任务已添加到后台: file_id=f09e21b7-78d5-441e-bc47-1e17ec9af8bb
INFO:     172.31.128.83:49538 - "POST /api/documents/process HTTP/1.1" 200 OK
INFO:app.services.document_service:开始处理文件: file_id=f09e21b7-78d5-441e-bc47-1e17ec9af8bb, url=https://fmqreoeqzqdaqdtgqzkc.supabase.co/storage/v1/object/public/files/8447d0a2-d505-47b6-bd50-51a5c97616e2/1fyn5hnrpid.pdf
INFO:app.services.document_service:更新文件状态为处理中: file_id=f09e21b7-78d5-441e-bc47-1e17ec9af8bb
INFO:httpx:HTTP Request: PATCH https://fmqreoeqzqdaqdtgqzkc.supabase.co/rest/v1/files?id=eq.f09e21b7-78d5-441e-bc47-1e17ec9af8bb "HTTP/2 200 OK"
INFO:app.services.supabase:文件状态已更新: file_id=f09e21b7-78d5-441e-bc47-1e17ec9af8bb, status=processing
INFO:httpx:HTTP Request: GET https://fmqreoeqzqdaqdtgqzkc.supabase.co/storage/v1/object/public/files/8447d0a2-d505-47b6-bd50-51a5c97616e2/1fyn5hnrpid.pdf "HTTP/1.1 200 OK"
INFO:app.services.document_service:文件下载成功: https://fmqreoeqzqdaqdtgqzkc.supabase.co/storage/v1/object/public/files/8447d0a2-d505-47b6-bd50-51a5c97616e2/1fyn5hnrpid.pdf
INFO:app.services.document_service:开始保存临时文件: /tmp/tmpccf80vpx
ERROR:app.services.document_service:处理文件失败: Error loading /tmp/tmpccf80vpx
INFO:httpx:HTTP Request: PATCH https://fmqreoeqzqdaqdtgqzkc.supabase.co/rest/v1/files?id=eq.f09e21b7-78d5-441e-bc47-1e17ec9af8bb "HTTP/2 200 OK"
INFO:app.services.supabase:文件状态已更新: file_id=f09e21b7-78d5-441e-bc47-1e17ec9af8bb, status=error
INFO:app.services.document_service:临时文件已清理: /tmp/tmpccf80vpx
ERROR:    Exception in ASGI application
Traceback (most recent call last):
  File "/home/runner/workspace/.pythonlibs/lib/python3.10/site-packages/langchain_community/document_loaders/text.py", line 43, in lazy_load
    text = f.read()
  File "/nix/store/qlb1pg370bb647nj4dhc81y2jszvciz7-python3-3.10.16/lib/python3.10/codecs.py", line 322, in decode
    (result, consumed) = self._buffer_decode(data, self.errors, final)
UnicodeDecodeError: 'utf-8' codec can't decode byte 0xfe in position 28: invalid start byte

The above exception was the direct cause of the following exception:

Traceback (most recent call last):
  File "/home/runner/workspace/.pythonlibs/lib/python3.10/site-packages/uvicorn/protocols/http/h11_impl.py", line 403, in run_asgi
    result = await app(  # type: ignore[func-returns-value]
  File "/home/runner/workspace/.pythonlibs/lib/python3.10/site-packages/uvicorn/middleware/proxy_headers.py", line 60, in __call__
    return await self.app(scope, receive, send)
  File "/home/runner/workspace/.pythonlibs/lib/python3.10/site-packages/fastapi/applications.py", line 1054, in __call__
    await super().__call__(scope, receive, send)
  File "/home/runner/workspace/.pythonlibs/lib/python3.10/site-packages/starlette/applications.py", line 112, in __call__
    await self.middleware_stack(scope, receive, send)
  File "/home/runner/workspace/.pythonlibs/lib/python3.10/site-packages/starlette/middleware/errors.py", line 187, in __call__
    raise exc
  File "/home/runner/workspace/.pythonlibs/lib/python3.10/site-packages/starlette/middleware/errors.py", line 165, in __call__
    await self.app(scope, receive, _send)
  File "/home/runner/workspace/.pythonlibs/lib/python3.10/site-packages/starlette/middleware/cors.py", line 93, in __call__
    await self.simple_response(scope, receive, send, request_headers=headers)
  File "/home/runner/workspace/.pythonlibs/lib/python3.10/site-packages/starlette/middleware/cors.py", line 144, in simple_response
    await self.app(scope, receive, send)
  File "/home/runner/workspace/.pythonlibs/lib/python3.10/site-packages/starlette/middleware/exceptions.py", line 62, in __call__
    await wrap_app_handling_exceptions(self.app, conn)(scope, receive, send)
  File "/home/runner/workspace/.pythonlibs/lib/python3.10/site-packages/starlette/_exception_handler.py", line 53, in wrapped_app
    raise exc
  File "/home/runner/workspace/.pythonlibs/lib/python3.10/site-packages/starlette/_exception_handler.py", line 42, in wrapped_app
    await app(scope, receive, sender)
  File "/home/runner/workspace/.pythonlibs/lib/python3.10/site-packages/starlette/routing.py", line 715, in __call__
    await self.middleware_stack(scope, receive, send)
  File "/home/runner/workspace/.pythonlibs/lib/python3.10/site-packages/starlette/routing.py", line 735, in app
    await route.handle(scope, receive, send)
  File "/home/runner/workspace/.pythonlibs/lib/python3.10/site-packages/starlette/routing.py", line 288, in handle
    await self.app(scope, receive, send)
  File "/home/runner/workspace/.pythonlibs/lib/python3.10/site-packages/starlette/routing.py", line 76, in app
    await wrap_app_handling_exceptions(app, request)(scope, receive, send)
  File "/home/runner/workspace/.pythonlibs/lib/python3.10/site-packages/starlette/_exception_handler.py", line 53, in wrapped_app
    raise exc
  File "/home/runner/workspace/.pythonlibs/lib/python3.10/site-packages/starlette/_exception_handler.py", line 42, in wrapped_app
    await app(scope, receive, sender)
  File "/home/runner/workspace/.pythonlibs/lib/python3.10/site-packages/starlette/routing.py", line 74, in app
    await response(scope, receive, send)
  File "/home/runner/workspace/.pythonlibs/lib/python3.10/site-packages/starlette/responses.py", line 159, in __call__
    await self.background()
  File "/home/runner/workspace/.pythonlibs/lib/python3.10/site-packages/starlette/background.py", line 41, in __call__
    await task()
  File "/home/runner/workspace/.pythonlibs/lib/python3.10/site-packages/starlette/background.py", line 26, in __call__
    await self.func(*self.args, **self.kwargs)
  File "/home/runner/workspace/app/services/document_service.py", line 96, in process_file
    raise e
  File "/home/runner/workspace/app/services/document_service.py", line 69, in process_file
    documents = loader.load()
  File "/home/runner/workspace/.pythonlibs/lib/python3.10/site-packages/langchain_core/document_loaders/base.py", line 31, in load
    return list(self.lazy_load())
  File "/home/runner/workspace/.pythonlibs/lib/python3.10/site-packages/langchain_community/document_loaders/text.py", line 56, in lazy_load
    raise RuntimeError(f"Error loading {self.file_path}") from e
RuntimeError: Error loading /tmp/tmpccf80vpx